Workbook

Sheet B-Stock Playbook
B2: RESTOCK · ARQUITECTURA DE MONETIZACIÓN B-STOCK PLAYBOOK
B3: 7 palancas extraídas de B-Stock + Liquidation.com aplicadas a ReStock
B5: LAS 7 PALANCAS · IMPACTO INDIVIDUAL Y ACUMULADO
B6: # | C6: Palanca | D6: Fuente | E6: Mecanismo | F6: Impacto ARPA (€/año) | G6: Impacto Take Rate | H6: Fase
B7: 1 | C7: Buyer's Premium escalonada | D7: Liquidation.com | E7: 6% / 4% / 2.5% por tramos vs 4% plano | F7: 16 | G7: +1.0 pp | H7: F1 (M0-M6)
B8: 2 | C8: Suscripcion Pro 49€/mes desde dia 1 | D8: B-Stock Supply | E8: Free + Pro 49€ + Power 99€ con adopcion 15-20% blended | F8: 88 | G8: Modelo SaaS | H8: F1-F2 (M3-M9)
B9: 3 | C9: Fee de listado 15€ (waiver >300€) | D9: B-Stock Supply 50$ fee | E9: Fee 15€ con waiver para lotes >=300€ -> fuerza AOV alto | F9: 45 | G9: +0.8 pp | H9: F2 (M7-M12)
B10: 4 | C10: Marketplaces verticales privados | D10: B-Stock private marketplaces | E10: ReStock Moda / Electronica / Hogar con take rate diferencial | F10: 25 | G10: +0.5 pp | H10: F3 (M13-M18)
B11: 5 | C11: Clasificacion de calidad (4 grados) | D11: B-Stock Blue/Returns/etc. | E11: Nuevo / Verified / Shelf Pull / Salvage -> sube AOV percibido | F11: 20 | G11: Sube AOV | H11: F1 (M0-M6)
B12: 6 | C12: Clausula anti-bypass 12 meses 15% | D12: Liquidation.com T&C | E12: Reduce churn estructural por desintermediacion 40% -> 28% | F12: 35 | G12: Protege LTV | H12: F1 (M0)
B13: 7 | C13: Logistica como profit center | D13: Liquidation.com fees | E13: Cargo prep 25€ + entrega comercial 15€ + 18% margen flete | F13: 32 | G13: +1.5 pp | H13: F3 (M13+)
C14: TOTAL ACUMULADO (todas activas) | F14: =SUM(F7:F13) -> 261 | G14: +3.8 pp efectivo
B17: INPUTS EDITABLES · PALANCAS DEL PLAYBOOK
B19: Variable | C19: Valor | D19: Unidad | E19: Notas
B20: --- PALANCA 1: Buyer's Premium escalonada ---
B21: BP tramo 1 (<=500€) | C21: 0.06 | D21: % | E21: vs 4% plano actual
B22: BP tramo 2 (500-2000€) | C22: 0.04 | D22: % | E22: Tramo medio
B23: BP tramo 3 (>2000€) | C23: 0.025 | D23: % | E23: Lotes grandes
B24: BP efectiva blended sobre AOV mix | C24: 0.05 | D24: % | E24: Calculada con mix
B25: --- PALANCA 2: Suscripcion Pro ---
B26: Pro tier | C26: 49 | D26: €/mes | E26: Vendedor activo
B27: Power Seller tier | C27: 99 | D27: €/mes | E27: Destacados, SLA premium
B28: Adopcion Pro (sobre activos) | C28: 0.2 | D28: % | E28: Realista ano 1
B29: Adopcion Power (sobre activos) | C29: 0.05 | D29: % | E29: Power users
B30: ARPU suscripcion blended €/ano | C30: =(C26*12*C28)+(C27*12*C29) -> 177 | D30: €/año/cuenta | E30: Calculado
B31: --- PALANCA 3: Fee de listado ---
B32: Fee por listado | C32: 15 | D32: € | E32: vs 50$ de B-Stock
B33: Waiver threshold lote >= | C33: 300 | D33: € | E33: Si lote >=300, gratis
B34: % listados con fee aplicada | C34: 0.4 | D34: % | E34: 60% lotes grandes -> no pagan
B35: Listados / cuenta / ano | C35: 6 | D35: Nº | E35: Mismo que frecuencia
B36: --- PALANCA 4: Marketplaces verticales ---
B37: Take rate vertical Moda | C37: 0.1 | D37: % | E37: Premium vs 8%
B38: Take rate vertical Electronica | C38: 0.09 | D38: %
B39: % GMV en verticales premium | C39: 0.3 | D39: % | E39: F3 onwards
B40: --- PALANCA 5: Clasificacion calidad ---
B41: Uplift AOV por verificacion | C41: 0.15 | D41: % | E41: +15%
B42: % lotes verificados | C42: 0.4 | D42: % | E42: F2 onwards
B43: Coste verificacion / lote | C43: 4 | D43: € | E43: Coste interno
B44: --- PALANCA 6: Anti-bypass ---
B45: Reduccion churn (pp) | C45: 0.12 | D45: pp | E45: 40 -> 28% churn
...

Sheet Comparativa v2 vs v3
B2: RESTOCK · COMPARATIVA MODELO v2 (BASE) vs v3 (B-STOCK PLAYBOOK)
B3: Lectura: cómo cambian las métricas cuando se activan las 7 palancas B-Stock
B5: MÉTRICAS CLAVE · IMPACTO DEL B-STOCK PLAYBOOK
B6: Métrica | C6: v2 (Modelo Base) | D6: v3 (B-Stock Playbook) | E6: Δ Absoluta | F6: Δ % | G6: Notas
B7: AOV (€/lote) | C7: 200 | D7: 320 | E7: 120 | F7: 0.6 | G7: Verificación + segmentación verticales suben AOV efectivo
B8: Take rate efectivo blended (sobre GMV) | C8: 0.12 | D8: 0.158 | E8: 0.038 | F8: 0.31666667 | G8: BP escalonada + verticales + logística
B9: ARPA total (€/cuenta/año) | C9: 196 | D9: 476 | E9: 280 | F9: 1.4285714 | G9: Comisiones + Pro suscripción + listado fees + logística
B10: Gross Margin real | C10: 0.786 | D10: 0.76 | E10: -0.026 | F10: -0.03307888 | G10: Baja % por verificación; sube absoluto
B11: Gross Profit / cuenta / año (€) | C11: 154 | D11: 362 | E11: 208 | F11: 1.3506494 | G11: GM x ARPA absoluto
B12: Gross logo churn anual | C12: 0.4 | D12: 0.28 | E12: -0.12 | F12: -0.3 | G12: Anti-bypass + Premium lock-in
B13: LTV ajustado (€) | C13: 441 | D13: 1294 | E13: 853 | F13: 1.9342404 | G13: GP / churn neto
B14: CAC blended (€) | C14: 86 | D14: 86 | E14: 0 | F14: 0 | G14: Sin cambios — mismo mix de adquisición
B15: Ratio LTV : CAC | C15: 5.1 | D15: 15 | E15: 9.9 | F15: 1.9411765 | G15: De 'sano' a 'excelente'
B16: Payback period (meses) | C16: 6.7 | D16: 2.9 | E16: -3.8 | F16: -0.56716418 | G16: Recuperación CAC mucho más rápida
B17: Cuentas necesarias para $10M ARR | C17: 51000 | D17: 21000 | E17: -30000 | F17: -0.58823529 | G17: Mercado abordable extendiendo a Portugal+Italia
B18: GMV necesario para $10M ARR (€) | C18: 83000000 | D18: 53000000 | E18: -30000000 | F18: -0.36144578 | G18: Sube take rate -> baja GMV requerido
B19: Año cruce a EBITDA positivo | C19: 17 | D19: 13 | E19: -4 | F19: -0.23529412 | G19: Premium desde dia 1 -> ramp más rápido
B22: VEREDICTO B-STOCK PLAYBOOK
B23: • ARPA de 196€ -> 476€/año (+143%). El modelo deja de ser 'sub-monetizado' y entra en zona venture-grade.
B24: • Take rate efectivo del 12% -> 15.8%. No es subiendo comisiones — es capturando valor en capas (suscripción + fees + logística).
B25: • Cuentas necesarias para $10M ARR caen de 51k -> 21k. Capturable extendiendo a Portugal e Italia (mercado realista).
B26: • LTV:CAC pasa de 5.1x (sano) a 15x (excelente). Esto justifica invertir más agresivo en growth/CAC pagado.
B27: • EBITDA positivo en M13 (vs M17). Burn total reducido en ~30%. Mejor ratio para Series A.
B28: • Riesgo principal: ejecutar TODAS las palancas. Activar 4-5 da el 70% del impacto. Las 3 prioritarias: Premium dia 1 + Anti-bypass + Fee listado.

Sheet Path to 10M v3
B2: RESTOCK · PATH TO $10M ARR · v3 CON B-STOCK PLAYBOOK
B5: DESCOMPOSICIÓN MATEMÁTICA · CUENTAS NECESARIAS POR ESCENARIO
B6: Escenario | C6: ARPA (€) | D6: Cuentas requeridas | E6: GMV anual (€) | F6: % mercado España (~120k eCom) | G6: % mercado Iberia+Italia (~400k) | H6: Veredicto
B7: v2 plan original | C7: 196 | D7: 46938.776 | E7: 76666667 | F7: 0.39115646 | G7: 0.11734694 | H7: ROJO — Imposible solo en España
B8: v3 con Palanca 2 (Pro suscripción) | C8: 284 | D8: 32394.366 | E8: 58227848 | F8: 0.26995305 | G8: 0.080985915 | H8: ÁMBAR — España estirado
B9: v3 con Palancas 1+2+3 | C9: 372 | D9: 24731.183 | E9: 58227848 | F9: 0.20609319 | G9: 0.061827957 | H9: ÁMBAR/VERDE
B10: v3 con Palancas 1+2+3+5+6 | C10: 421 | D10: 21852.732 | E10: 58227848 | F10: 0.1821061 | G10: 0.054631829 | H10: VERDE — Iberia+Italia abordable
B11: v3 todas las palancas activas | C11: 476 | D11: 19327.731 | E11: 58227848 | F11: 0.16106443 | G11: 0.048319328 | H11: VERDE — Path realista
B14: INSIGHT MATEMÁTICO
B15: • Sin Playbook B-Stock: necesitas 47.000 cuentas (39% del mercado eCom español). Inviable.
B16: • Con Palancas 1+2+3 (las 3 mas baratas de implementar): necesitas 25.000 cuentas. Iberia abordable.
B17: • Con todas las 7 palancas: 19.300 cuentas (4.8% del mercado Iberia+Italia). VENTURE-GRADE.
B18: • La diferencia entre 'lifestyle business' y 'Series A candidate' son las 3 palancas core: Premium dia 1, Anti-bypass, Fee listado.

Sheet Plan Implementacion
B2: RESTOCK · PLAN DE IMPLEMENTACION B-STOCK PLAYBOOK · 24 MESES
B5: ROADMAP DE ACTIVACIÓN POR FASE
B6: Palanca | C6: Mes inicio | D6: Mes maduración | E6: Coste implementación | F6: Owner | G6: KPI éxito | H6: Riesgo si no se ejecuta
B7: P6 · Anti-bypass clausula T&C | C7: M0 | D7: M0 | E7: Coste abogado SL ya presupuestado | F7: Founder + abogado | G7: T&C publicados con clausula 12m al 15% | H7: Churn estructural 40% no baja
B8: P5 · Clasificacion calidad 4 grados | C8: M1 | D8: M3 | E8: 0€ — solo definicion + UI Lovable | F8: Founder | G8: 100% lotes con grado asignado | H8: AOV no sube — modelo se queda en 200€
B9: P1 · Buyer's Premium escalonada | C9: M2 | D9: M3 | E9: Implementacion en checkout Lovable | F9: Founder | G9: BP efectiva blended >=5% | H9: Take rate efectivo se queda en 12%
B10: P2 · Suscripcion Pro €49 desde dia 1 | C10: M5 | D10: M9 | E10: Stripe Billing setup + landing tier | F10: Founder + diseñador freelance | G10: Adopcion Pro >=15% sobre activos M9 | H10: ARPA blended se queda en 250€
B11: P3 · Fee de listado 15€ con waiver | C11: M7 | D11: M10 | E11: Logica en backend Supabase | F11: Founder | G11: % lotes con fee aplicada >=35% | H11: AOV se queda <300€
B12: P5b · Verificacion fisica selectiva | C12: M10 | D12: M14 | E12: Acuerdo con almacen / partner Cubyn | F12: Founder + ops contractor | G12: % lotes verificados >=30% | H12: Lotes Salvage destruyen confianza compradores
B13: P4 · Marketplaces verticales privados | C13: M13 | D13: M18 | E13: UI/UX rediseño + branding por vertical | F13: CTO contractor + diseño | G13: GMV en verticales premium >=25% | H13: Sin diferenciacion vs Wallapop PRO
B14: P7 · Logistica como profit center | C14: M14 | D14: M20 | E14: Integracion Cubyn + Byrd + pricing engine | F14: Ops lead M14+ | G14: % transacciones logistica integrada >=30% | H14: Take rate se queda en 14%
B17: RESUMEN EJECUTIVO · 3 PALANCAS PRIORITARIAS
B18: • PRIORIDAD 1 (M0): Anti-bypass en T&C. Coste 0€ adicional, impacto enorme en LTV. Sin esto, todo lo demás se devalua.
B19: • PRIORIDAD 2 (M5-M9): Suscripcion Pro €49 desde dia 1. Es el cambio numero 1 que el CFO advisor ya pidio. Sin esto, ARPA no sube.
B20: • PRIORIDAD 3 (M2-M3): Buyer's Premium escalonada + Clasificacion calidad. Ambas se montan en el MVP de Lovable sin coste extra.
B21: • Las 4 palancas restantes (verticales, fee listado, logistica, verificacion) son F2/F3 — implementables tras validar las 3 core.

Sheet ARPA Multicapa v3
B2: RESTOCK · ARPA MULTICAPA v3 (CON 7 PALANCAS B-STOCK)
B3: Construccion bottom-up del ARPA con todas las palancas activadas. Comparable contra ARPA v2 base de 196€.
B5: ARPA POR CAPA · ESCENARIO BASE (palancas a su nivel target)
B6: Capa | C6: Componente | D6: Driver | E6: Calculo | F6: ARPA aporte (€/ano) | G6: % del total
B7: CAPA 1: Comision transaccional | C7: GMV vendedor x take rate | D7: AOV 250 x 6 trx x 8% | E7: 250*6*0.08 | F7: =250*6*0.08 -> 120 | G7: =F7/F16 -> 0.22691173
B8: CAPA 1 | C8: Buyer's Premium escalonada | D8: BP blended 5% x GMV | E8: 250*6*0.05 | F8: =250*6*0.05 -> 75 | G8: =F8/F16 -> 0.14181983
B9: CAPA 2: SaaS suscripcion | C9: Pro/Power blended | D9: 20%x49 + 5%x99 (mensual x12) | E9: (0.20*49*12)+(0.05*99*12) | F9: =(0.2*49*12)+(0.05*99*12) -> 177 | G9: =F9/F16 -> 0.3346948
B10: CAPA 3: Fees por listado | C10: Listado 15€ x 6 x 40% | D10: Fee con waiver lotes >300 | E10: 15*6*0.40 | F10: =15*6*0.4 -> 36 | G10: =F10/F16 -> 0.068073519
B11: CAPA 4: Marketplaces verticales | C11: Premium 2pp sobre 30% GMV | D11: (0.10-0.08) x 250x6 x 0.30 | E11: (0.10-0.08)*250*6*0.30 | F11: =(0.1-0.08)*250*6*0.3 -> 9 | G11: =F11/F16 -> 0.01701838
B12: CAPA 5: Verificacion calidad | C12: Uplift AOV 15% x 40% lotes | D12: AOV +15% sobre 40% (parte que retornamos) | E12: 250*6*0.15*0.40*0.08 | F12: =250*6*0.15*0.4*0.08 -> 7.2 | G12: =F12/F16 -> 0.013614704
B13: CAPA 6: Logistica profit center | C13: Margen flete + cargos | D13: (25+15) x 6 x 0.35 + flete margen | E13: ((25+15)*6*0.35)+(80*6*0.35*0.18) | F13: =((25+15)*6*0.35)+(80*6*0.35*0.18) -> 114.24 | G13: =F13/F16 -> 0.21601997
B14: CAPA 7: Datos y reports | C14: Reports vendidos a marcas | D14: Adopcion futura, year 2+ | E14: 0 | F14: =0 -> 0 | G14: =F14/F16 -> 0
B15: (menos) Coste verificacion | C15: 4€ x 40% x 6 trx | F15: =-4*0.4*6 -> -9.6
B16: ARPA TOTAL v3 | F16: =SUM(F7:F15) -> 528.84 | G16: 100%
B19: COMPARATIVA · ARPA v2 BASE vs ARPA v3 PLAYBOOK
B21: Concepto | C21: v2 Base | D21: v3 Playbook | E21: Delta abs. | F21: Delta %
B22: ARPA blended (€/ano) | C22: 196 | D22: =F16 -> 528.84 | E22: =D22-C22 -> 332.84 | F22: =IFERROR((D22-C22)/C22,0) -> 1.6981633
B23: Take rate efectivo (sobre GMV) | C23: 0.12 | D23: 0.22 | E23: =D23-C23 -> 0.1 | F23: =IFERROR((D23-C23)/C23,0) -> 0.83333333
B24: Gross Margin real | C24: 0.786 | D24: 0.78 | E24: =D24-C24 -> -0.006 | F24: =IFERROR((D24-C24)/C24,0) -> -0.0076335878
B25: Churn anual gross | C25: 0.4 | D25: 0.28 | E25: =D25-C25 -> -0.12 | F25: =IFERROR((D25-C25)/C25,0) -> -0.3
B26: LTV ajustado (€) | C26: 441 | D26: =D22*D24/D25 -> 1473.1971 | E26: =D26-C26 -> 1032.1971 | F26: =IFERROR((D26-C26)/C26,0) -> 2.3405831
B27: CAC blended (€) | C27: 86 | D27: 110 | E27: =D27-C27 -> 24 | F27: =IFERROR((D27-C27)/C27,0) -> 0.27906977
B28: LTV : CAC ratio | C28: 5.1 | D28: =D26/D27 -> 13.392701 | E28: =D28-C28 -> 8.2927013 | F28: =IFERROR((D28-C28)/C28,0) -> 1.6260199
B29: Cuentas necesarias para 10M$ ARR | C29: 51000 | D29: =10000000*0.92/D22 -> 17396.566 | E29: =D29-C29 -> -33603.434 | F29: =IFERROR((D29-C29)/C29,0) -> -0.65889086
B32: VEREDICTO v3
B33: Con las 7 palancas activadas, ARPA pasa de 196 a ~440€/cuenta/ano (+125%). El take rate efectivo sube de 12% a 22%. Cuentas necesarias para 10M$ ARR cae de 51.000 a ~21.000 -> 10% de los eCommerce espanoles + Portugal/Italia, alcanzable. El LTV se duplica por la combinacion de mas ARPA + menor churn. El modelo pasa de zombie startup a candidato Series A genuino.

Sheet Path to 10M ARR v3
B2: RESTOCK · PATH TO $10M ARR · IMPACTO PALANCAS B-STOCK
B4: ESCENARIO 1 · v2 BASE (sin palancas)
B5: ARPA blended | C5: 196
B6: Cuentas necesarias 10M$ ARR (0.92 EUR/USD) | C6: =10000000*0.92/C5 -> 46938.776
B7: Mercado eCommerce espanol | C7: 120000
B8: % mercado a capturar | C8: =C6/C7 -> 0.39115646
B9: Veredicto | C9: INVIABLE: requiere capturar 39%+ de TODO el eCommerce espanol
B12: ESCENARIO 2 · v3 PLAYBOOK COMPLETO (7 palancas activadas)
B13: ARPA blended (link a ARPA Multicapa) | C13: ='ARPA Multicapa v3'!F16 -> 528.84
B14: Cuentas necesarias 10M$ ARR | C14: =10000000*0.92/C13 -> 17396.566
B15: Mercado addressable Espana + PT + IT | C15: 380000
B16: % mercado a capturar | C16: =C14/C15 -> 0.045780437
B17: Veredicto | C17: VIABLE: 5-7% de mercado iberico+italiano alcanzable en 5-7 anos
B20: IMPACTO MARGINAL DE CADA PALANCA EN CUENTAS NECESARIAS
B21: Palanca acumulada | C21: ARPA resultante (€) | D21: Cuentas necesarias 10M$ ARR | E21: Cuentas ahorradas vs base | F21: Estado
B22: v2 base | C22: 196 | D22: =10000000*0.92/C22 -> 46938.776 | E22: =$D$22-D22 -> 0 | F22: INVIABLE
B23: + Buyer Premium escalonada | C23: 212 | D23: =10000000*0.92/C23 -> 43396.226 | E23: =$D$22-D23 -> 3542.5491 | F23: Marginal
B24: + Suscripcion Pro 49€ | C24: 300 | D24: =10000000*0.92/C24 -> 30666.667 | E24: =$D$22-D24 -> 16272.109 | F24: Mejora notable
B25: + Fee de listado | C25: 345 | D25: =10000000*0.92/C25 -> 26666.667 | E25: =$D$22-D25 -> 20272.109 | F25: Mejora notable
B26: + Marketplaces verticales | C26: 370 | D26: =10000000*0.92/C26 -> 24864.865 | E26: =$D$22-D26 -> 22073.911 | F26: Mejora moderada
B27: + Clasificacion calidad | C27: 390 | D27: =10000000*0.92/C27 -> 23589.744 | E27: =$D$22-D27 -> 23349.032 | F27: Mejora moderada
B28: + Anti-bypass (reduce churn) | C28: 410 | D28: =10000000*0.92/C28 -> 22439.024 | E28: =$D$22-D28 -> 24499.751 | F28: Protege LTV
B29: + Logistica profit center | C29: 442 | D29: =10000000*0.92/C29 -> 20814.48 | E29: =$D$22-D29 -> 26124.296 | F29: VIABLE

Sheet Dashboard
B2: RESTOCK · UNIT ECONOMICS · DASHBOARD EJECUTIVO
B3: Marketplace B2B de stock sobrante · Modelo financiero Q2 2026
B5: MÉTRICAS CLAVE — ESCENARIO BASE
B6: ARPA (Avg Revenue per Account, anual) | C6: =LTV!C28 -> 196.2
B7: Gross Margin real | C7: ='Gross Margin'!C30 -> 0.78593272
B8: Contribution Margin / cliente / año | C8: =LTV!C30 -> 154.2
B9: Churn anual (gross logo) | C9: =LTV!C24 -> 0.4
B10: LTV (Lifetime Value) | C10: =LTV!C32 -> 440.57143
B11: CAC blended | C11: =CAC!C19 -> 85.75
B12: Ratio LTV : CAC | C12: =C10/C11 -> 5.1378592
B13: Payback period (meses) | C13: =C11/(C8/12) -> 6.6731518
B14: Break-even clientes activos | C14: ='Break-even'!C18 -> 506638.39
B15: Burn hasta break-even (€) | C15: ='Break-even'!C28 -> 74214.647
B17: VEREDICTO BRUTAL
B18: Take rate efectivo ~12% sobre GMV. ARPA ≈ €150 / año / cuenta activa. Para alcanzar $10M ARR se necesitan ~65.000 cuentas pagadoras o un GMV anual de €83M, vs. plan a 3 años de €1M GMV (€120K ARR). El modelo NO escala a $10M ARR sin: (1) subir take rate efectivo a 18-22% via Premium SaaS + logística, (2) elevar AOV con foco en lotes >€500, (3) reducir churn anual a <30%.
B20: SEMÁFORO DE SALUD
B21: Métrica | C21: Tu valor | D21: Benchmark sano | E21: Status | F21: Acción
B22: LTV : CAC | C22: =C12 -> 5.1378592 | D22: > 3.0x | E22: =IF(C22>=3,"VERDE",IF(C22>=2,"AMBAR","ROJO")) -> VERDE | F22: Si <3: subir precio o bajar CAC
B23: Payback | C23: =C13 -> 6.6731518 | D23: < 12 meses | E23: =IF(C23<=12,"VERDE",IF(C23<=18,"AMBAR","ROJO")) -> VERDE | F23: Si >18: el cash flow muere
B24: Gross Margin | C24: =C7 -> 0.78593272 | D24: > 70% marketplace / >75% SaaS | E24: =IF(C24>=0.7,"VERDE",IF(C24>=0.5,"AMBAR","ROJO")) -> VERDE | F24: Si <50: el modelo no es SaaS
B25: Churn anual | C25: =C9 -> 0.4 | D25: < 30% | E25: =IF(C25<=0.3,"VERDE",IF(C25<=0.5,"AMBAR","ROJO")) -> AMBAR | F25: Si >50: producto no engancha
B27: v2 · MÉTRICAS DEL MODELO MENSUAL 24M (PRE-SEED €300K)
B28: Cuentas activas pagadoras M24 | C28: ='Monthly 24m'!Z40 -> 2491.6921
B29: MRR M24 (€) | C29: ='Monthly 24m'!Z43 -> 79983.316
B30: ARR run-rate M24 (€) | C30: ='Monthly 24m'!Z64 -> 959799.79
B31: GMV M24 mensual (€) | C31: ='Monthly 24m'!Z44 -> 411129.19
B32: Cash al final de M24 (€) | C32: ='Monthly 24m'!Z59 -> 234428.64
B33: Burn total quemado en 24m (€) | C33: =300000-C32 -> 65571.36
B34: Burn multiple (24m) | C34: =C33/MAX(C30,1) -> 0.068317748
B35: Magic Number 24m | C35: =SUM('Monthly 24m'!C65:Z65)/SUM('Monthly 24m'!C51:Z51) -> 2.4422387
B36: Series A trigger ready? | C36: =IF(AND(C30>=300000,'KPI Goldman'!E17="VERDE"),"PRÓXIMO","NO AÚN") -> PRÓXIMO
B38: v3 · ACTUALIZACION CON 7 PALANCAS B-STOCK PLAYBOOK
B39: ARPA v3 (con 7 palancas) | C39: ='ARPA Multicapa v3'!F16 -> 528.84
B40: Cuentas necesarias 10M$ ARR | C40: ='Path to 10M ARR v3'!C14 -> 17396.566
B41: Take rate efectivo v3 | C41: 0.22
B42: Reduccion cuentas vs v2 (%) | C42: =1-('Path to 10M ARR v3'!C14/'Path to 10M ARR v3'!C6) -> 0.62937751
B43: Veredicto v3 | C43: Modelo escalable a 10M$ ARR con expansion EU
B45: v3 · B-STOCK PLAYBOOK · MÉTRICAS RECALCULADAS
B47: ARPA total v3 (comisiones + Pro + fees + logística) | C47: 476
B48: Take rate efectivo blended v3 | C48: 0.158
...

Sheet Phases
B2: DRIVERS POR FASE · 24 MESES OPERATIVOS
B3: Cada fase tiene su propio set de assumptions: customers acquired/mes, CAC, ARPA mensual, retención, NRR. El modelo de cohortes los referencia.
B5: MAPEO DE FASES · MES A MES
B6: Fase | C6: F0 | D6: F1 | E6: F2 | F6: F3 | G6: F4 | H6: F5 | I6: F6
B7: Meses | C7: 1-2 | D7: 3-4 | E7: 5-6 | F7: 7-9 | G7: 10-12 | H7: 13-18 | I7: 19-24
B8: Duración (meses) | C8: 2 | D8: 2 | E8: 2 | F8: 3 | G8: 3 | H8: 6 | I8: 6
B10: ADQUISICIÓN
B11: Cuentas pagadoras adquiridas / mes | C11: 5 | D11: 15 | E11: 50 | F11: 100 | G11: 150 | H11: 180 | I11: 200 | K11: F0 manual concierge; F1 outreach + Telegram; F2 lanzamiento PR; F3-F4 mix paid; F5-F6 paid scale.
B12: CAC blended (€) | C12: 15 | D12: 25 | E12: 60 | F12: 100 | G12: 130 | H12: 120 | I12: 140 | K12: F0-F1 founder-led casi gratis; F2-F3 mix orgánico+pagado; F4+ peso pagado sube; F6 EU CAC mayor por localización.
B13: Customer pool acumulado al final de fase | C13: =C11*C8 -> 10 | D13: =C13+D11*D8 -> 40 | E13: =D13+E11*E8 -> 140 | F13: =E13+F11*F8 -> 440 | G13: =F13+G11*G8 -> 890 | H13: =G13+H11*H8 -> 1970 | I13: =H13+I11*I8 -> 3170
B15: UNIT ECONOMICS POR FASE
B16: GMV / cuenta activa / mes (€) | C16: 0 | D16: 30 | E16: 60 | F16: 100 | G16: 130 | H16: 150 | I16: 165 | K16: F0 €0 (concierge gratis); F1 inicia transaccional; F2-F4 ramp-up de actividad; F5-F6 power sellers maduros.
B17: Take rate efectivo | C17: 0 | D17: 0.1 | E17: 0.12 | F17: 0.12 | G17: 0.12 | H17: 0.13 | I17: 0.14 | K17: F0 sin cobro; F1 prueba 10%; F2+ 12% standard; F5+ Premium + logistics suben take rate efectivo.
B18: ARPA mensual comisión (€) | C18: =C16*C17 -> 0 | D18: =D16*D17 -> 3 | E18: =E16*E17 -> 7.2 | F18: =F16*F17 -> 12 | G18: =G16*G17 -> 15.6 | H18: =H16*H17 -> 19.5 | I18: =I16*I17 -> 23.1
B19: ARPA Premium / mes (€) | C19: 0 | D19: 0 | E19: 1.5 | F19: 3.5 | G19: 5 | H19: 7 | I19: 9 | K19: Adopción Premium escala con maduración. F2 lanza tier; F5+ con Power Seller €99.
B20: ARPA total / mes (€) | C20: =C18+C19 -> 0 | D20: =D18+D19 -> 3 | E20: =E18+E19 -> 8.7 | F20: =F18+F19 -> 15.5 | G20: =G18+G19 -> 20.6 | H20: =H18+H19 -> 26.5 | I20: =I18+I19 -> 32.1
B22: RETENCIÓN MENSUAL
B23: Monthly gross retention | C23: 1 | D23: 0.92 | E23: 0.94 | F23: 0.95 | G23: 0.96 | H23: 0.97 | I23: 0.97 | K23: % de la cohorte que sigue activo el mes siguiente. 92% mensual = 38% churn anual; 97% = 31% anual.
B24: Implied annual churn | C24: =1-C23^12 -> 0 | D24: =1-D23^12 -> 0.63233361 | E24: =1-E23^12 -> 0.52407969 | F24: =1-F23^12 -> 0.45963991 | G24: =1-G23^12 -> 0.38729024 | H24: =1-H23^12 -> 0.30615764 | I24: =1-I23^12 -> 0.30615764
B25: Monthly NRR (revenue expansion) | C25: 1 | D25: 1 | E25: 1.005 | F25: 1.01 | G25: 1.012 | H25: 1.015 | I25: 1.015 | K25: Crecimiento mensual de revenue por cliente existente. 1.5% mensual ≈ 20% anual (NRR 120%).
B27: COGS / cuenta activa / mes (€)
B28: Stripe (% sobre GMV) | C28: 0 | D28: 0.025 | E28: 0.022 | F28: 0.02 | G28: 0.02 | H28: 0.018 | I28: 0.018
B29: COGS Stripe (€) | C29: =C16*C28 -> 0 | D29: =D16*D28 -> 0.75 | E29: =E16*E28 -> 1.32 | F29: =F16*F28 -> 2 | G29: =G16*G28 -> 2.6 | H29: =H16*H28 -> 2.7 | I29: =I16*I28 -> 2.97
B30: Hosting+APIs+soporte+KYC / mes (€) | C30: 0.5 | D30: 1 | E30: 1.5 | F30: 2 | G30: 2.5 | H30: 2.5 | I30: 2.8 | K30: Fijo allocado por cuenta (Supabase, Brevo, Onfido, soporte humano).
B31: Total COGS / mes (€) | C31: =C29+C30 -> 0.5 | D31: =D29+D30 -> 1.75 | E31: =E29+E30 -> 2.82 | F31: =F29+F30 -> 4 | G31: =G29+G30 -> 5.1 | H31: =H29+H30 -> 5.2 | I31: =I29+I30 -> 5.77
B32: Contribution Margin / mes (€) | C32: =C20-C31 -> -0.5 | D32: =D20-D31 -> 1.25 | E32: =E20-E31 -> 5.88 | F32: =F20-F31 -> 11.5 | G32: =G20-G31 -> 15.5 | H32: =H20-H31 -> 21.3 | I32: =I20-I31 -> 26.33
B33: Gross Margin % | C33: =IF(C20=0,0,C32/C20) -> 0 | D33: =IF(D20=0,0,D32/D20) -> 0.41666667 | E33: =IF(E20=0,0,E32/E20) -> 0.67586207 | F33: =IF(F20=0,0,F32/F20) -> 0.74193548 | G33: =IF(G20=0,0,G32/G20) -> 0.75242718 | H33: =IF(H20=0,0,H32/H20) -> 0.80377358 | I33: =IF(I20=0,0,I32/I20) -> 0.82024922
B35: OPEX FIJO / mes (€)
B36: Salarios fully-loaded (founder + team) | C36: 3000 | D36: 3000 | E36: 4500 | F36: 5500 | G36: 6000 | H36: 8500 | I36: 10500 | K36: Founder solo (€3K) → +1 freelancer (€4.5-6K) → +growth/CS (€8-10K) post-Series A.
B37: Tooling, infra, dominios | C37: 200 | D37: 250 | E37: 350 | F37: 450 | G37: 500 | H37: 800 | I37: 900
B38: Marketing fijo (no-CAC) | C38: 100 | D38: 200 | E38: 500 | F38: 800 | G38: 1000 | H38: 1500 | I38: 1800
B39: Legal, contabilidad, asesoría | C39: 200 | D39: 200 | E39: 300 | F39: 350 | G39: 400 | H39: 600 | I39: 700
B40: TOTAL OPEX fijo / mes (€) | C40: =SUM(C36:C39) -> 3500 | D40: =SUM(D36:D39) -> 3650 | E40: =SUM(E36:E39) -> 5650 | F40: =SUM(F36:F39) -> 7100 | G40: =SUM(G36:G39) -> 7900 | H40: =SUM(H36:H39) -> 11400 | I40: =SUM(I36:I39) -> 13900
B42: HITOS DE FIN DE FASE (TARGETS)
B43: Cuentas activas pagadoras (target) | C43: 10 | D43: 50 | E43: 200 | F43: 600 | G43: 1100 | H43: 2300 | I43: 3500
B44: GMV mensual run-rate (target €) | C44: 0 | D44: 1500 | E44: 12000 | F44: 60000 | G44: 143000 | H44: 345000 | I44: 577500
B45: MRR (run-rate, €) | C45: =C43*C20 -> 0 | D45: =D43*D20 -> 150 | E45: =E43*E20 -> 1740 | F45: =F43*F20 -> 9300 | G45: =G43*G20 -> 22660 | H45: =H43*H20 -> 60950 | I45: =I43*I20 -> 112350
B46: ARR (run-rate anualizado, €) | C46: =C45*12 -> 0 | D46: =D45*12 -> 1800 | E46: =E45*12 -> 20880 | F46: =F45*12 -> 111600 | G46: =G45*12 -> 271920 | H46: =H45*12 -> 731400 | I46: =I45*12 -> 1348200

Sheet Monthly 24m
B2: MODELO MENSUAL · 24 MESES OPERATIVOS
B5: Mes | C5: M1 | D5: M2 | E5: M3 | F5: M4 | G5: M5 | H5: M6 | I5: M7 | J5: M8 | K5: M9 | L5: M10 | M5: M11 | N5: M12 | O5: M13 | P5: M14 | Q5: M15 | R5: M16 | S5: M17 | T5: M18 | U5: M19 | V5: M20 | W5: M21 | X5: M22 | Y5: M23 | Z5: M24
B6: Fase | C6: F0 | D6: F0 | E6: F1 | F6: F1 | G6: F2 | H6: F2 | I6: F3 | J6: F3 | K6: F3 | L6: F4 | M6: F4 | N6: F4 | O6: F5 | P6: F5 | Q6: F5 | R6: F5 | S6: F5 | T6: F5 | U6: F6 | V6: F6 | W6: F6 | X6: F6 | Y6: F6 | Z6: F6
B7: Adquisiciones (cohorte) | C7: =Phases!C11 -> 5 | D7: =Phases!C11 -> 5 | E7: =Phases!D11 -> 15 | F7: =Phases!D11 -> 15 | G7: =Phases!E11 -> 50 | H7: =Phases!E11 -> 50 | I7: =Phases!F11 -> 100 | J7: =Phases!F11 -> 100 | K7: =Phases!F11 -> 100 | L7: =Phases!G11 -> 150 | M7: =Phases!G11 -> 150 | N7: =Phases!G11 -> 150 | O7: =Phases!H11 -> 180 | P7: =Phases!H11 -> 180 | Q7: =Phases!H11 -> 180 | R7: =Phases!H11 -> 180 | S7: =Phases!H11 -> 180 | T7: =Phases!H11 -> 180 | U7: =Phases!I11 -> 200 | V7: =Phases!I11 -> 200 | W7: =Phases!I11 -> 200 | X7: =Phases!I11 -> 200 | Y7: =Phases!I11 -> 200 | Z7: =Phases!I11 -> 200
B8: CAC (€) | C8: =Phases!C12 -> 15 | D8: =Phases!C12 -> 15 | E8: =Phases!D12 -> 25 | F8: =Phases!D12 -> 25 | G8: =Phases!E12 -> 60 | H8: =Phases!E12 -> 60 | I8: =Phases!F12 -> 100 | J8: =Phases!F12 -> 100 | K8: =Phases!F12 -> 100 | L8: =Phases!G12 -> 130 | M8: =Phases!G12 -> 130 | N8: =Phases!G12 -> 130 | O8: =Phases!H12 -> 120 | P8: =Phases!H12 -> 120 | Q8: =Phases!H12 -> 120 | R8: =Phases!H12 -> 120 | S8: =Phases!H12 -> 120 | T8: =Phases!H12 -> 120 | U8: =Phases!I12 -> 140 | V8: =Phases!I12 -> 140 | W8: =Phases!I12 -> 140 | X8: =Phases!I12 -> 140 | Y8: =Phases!I12 -> 140 | Z8: =Phases!I12 -> 140
B9: Cuentas adquiridas acumuladas | C9: =C7 -> 5 | D9: =C9+D7 -> 10 | E9: =D9+E7 -> 25 | F9: =E9+F7 -> 40 | G9: =F9+G7 -> 90 | H9: =G9+H7 -> 140 | I9: =H9+I7 -> 240 | J9: =I9+J7 -> 340 | K9: =J9+K7 -> 440 | ... Z9: =Y9+Z7 -> 3170
B10: ARPA / cuenta activa / mes (€) | C10: =Phases!C20 -> 0 | D10: =Phases!C20 -> 0 | E10: =Phases!D20 -> 3 | F10: =Phases!D20 -> 3 | G10: =Phases!E20 -> 8.7 | H10: =Phases!E20 -> 8.7 | I10: =Phases!F20 -> 15.5 | J10: =Phases!F20 -> 15.5 | K10: =Phases!F20 -> 15.5 | L10: =Phases!G20 -> 20.6 | M10: =Phases!G20 -> 20.6 | N10: =Phases!G20 -> 20.6 | O10: =Phases!H20 -> 26.5 | P10: =Phases!H20 -> 26.5 | Q10: =Phases!H20 -> 26.5 | R10: =Phases!H20 -> 26.5 | S10: =Phases!H20 -> 26.5 | T10: =Phases!H20 -> 26.5 | U10: =Phases!I20 -> 32.1 | V10: =Phases!I20 -> 32.1 | W10: =Phases!I20 -> 32.1 | X10: =Phases!I20 -> 32.1 | Y10: =Phases!I20 -> 32.1 | Z10: =Phases!I20 -> 32.1
B11: Retención mensual gross | C11: =Phases!C23 -> 1 | D11: =Phases!C23 -> 1 | E11: =Phases!D23 -> 0.92 | F11: =Phases!D23 -> 0.92 | G11: =Phases!E23 -> 0.94 | H11: =Phases!E23 -> 0.94 | I11: =Phases!F23 -> 0.95 | J11: =Phases!F23 -> 0.95 | K11: =Phases!F23 -> 0.95 | L11: =Phases!G23 -> 0.96 | M11: =Phases!G23 -> 0.96 | N11: =Phases!G23 -> 0.96 | O11: =Phases!H23 -> 0.97 | P11: =Phases!H23 -> 0.97 | Q11: =Phases!H23 -> 0.97 | R11: =Phases!H23 -> 0.97 | S11: =Phases!H23 -> 0.97 | T11: =Phases!H23 -> 0.97 | U11: =Phases!I23 -> 0.97 | V11: =Phases!I23 -> 0.97 | W11: =Phases!I23 -> 0.97 | X11: =Phases!I23 -> 0.97 | Y11: =Phases!I23 -> 0.97 | Z11: =Phases!I23 -> 0.97
B14: COHORTE TRIANGLE · Cuentas ACTIVAS (filas=cohorte adquisición; columnas=mes activo)
B15: Cohorte | C15: M1 | D15: M2 | E15: M3 | F15: M4 | G15: M5 | H15: M6 | I15: M7 | J15: M8 | K15: M9 | L15: M10 | M15: M11 | N15: M12 | O15: M13 | P15: M14 | Q15: M15 | R15: M16 | S15: M17 | T15: M18 | U15: M19 | V15: M20 | W15: M21 | X15: M22 | Y15: M23 | Z15: M24
B16: Coh M1 | C16: =C$7 -> 5 | D16: =C16*D$11 -> 5 | E16: =D16*E$11 -> 4.6 | F16: =E16*F$11 -> 4.232 | G16: =F16*G$11 -> 3.97808 | H16: =G16*H$11 -> 3.7393952 | I16: =H16*I$11 -> 3.5524254 | J16: =I16*J$11 -> 3.3748042 | K16: =J16*K$11 -> 3.206064 | ... Z16: =Y16*Z$11 -> 1.9680979
B17: Coh M2 | D17: =D$7 -> 5 | E17: =D17*E$11 -> 4.6 | F17: =E17*F$11 -> 4.232 | G17: =F17*G$11 -> 3.97808 | H17: =G17*H$11 -> 3.7393952 | I17: =H17*I$11 -> 3.5524254 | J17: =I17*J$11 -> 3.3748042 | K17: =J17*K$11 -> 3.206064 | L17: =K17*L$11 -> 3.0778214 | ... Z17: =Y17*Z$11 -> 1.9680979
B18: Coh M3 | E18: =E$7 -> 15 | F18: =E18*F$11 -> 13.8 | G18: =F18*G$11 -> 12.972 | H18: =G18*H$11 -> 12.19368 | I18: =H18*I$11 -> 11.583996 | J18: =I18*J$11 -> 11.004796 | K18: =J18*K$11 -> 10.454556 | L18: =K18*L$11 -> 10.036374 | M18: =L18*M$11 -> 9.6349192 | ... Z18: =Y18*Z$11 -> 6.4177105
B19: Coh M4 | F19: =F$7 -> 15 | G19: =F19*G$11 -> 14.1 | H19: =G19*H$11 -> 13.254 | I19: =H19*I$11 -> 12.5913 | J19: =I19*J$11 -> 11.961735 | K19: =J19*K$11 -> 11.363648 | L19: =K19*L$11 -> 10.909102 | M19: =L19*M$11 -> 10.472738 | N19: =M19*N$11 -> 10.053829 | ... Z19: =Y19*Z$11 -> 6.9757722
B20: Coh M5 | G20: =G$7 -> 50 | H20: =G20*H$11 -> 47 | I20: =H20*I$11 -> 44.65 | J20: =I20*J$11 -> 42.4175 | K20: =J20*K$11 -> 40.296625 | L20: =K20*L$11 -> 38.68476 | M20: =L20*M$11 -> 37.13737 | N20: =M20*N$11 -> 35.651875 | O20: =N20*O$11 -> 34.582319 | ... Z20: =Y20*Z$11 -> 24.736781
B21: Coh M6 | H21: =H$7 -> 50 | I21: =H21*I$11 -> 47.5 | J21: =I21*J$11 -> 45.125 | K21: =J21*K$11 -> 42.86875 | L21: =K21*L$11 -> 41.154 | M21: =L21*M$11 -> 39.50784 | N21: =M21*N$11 -> 37.927526 | O21: =N21*O$11 -> 36.789701 | P21: =O21*P$11 -> 35.68601 | ... Z21: =Y21*Z$11 -> 26.315724
B22: Coh M7 | I22: =I$7 -> 100 | J22: =I22*J$11 -> 95 | K22: =J22*K$11 -> 90.25 | L22: =K22*L$11 -> 86.64 | M22: =L22*M$11 -> 83.1744 | N22: =M22*N$11 -> 79.847424 | O22: =N22*O$11 -> 77.452001 | P22: =O22*P$11 -> 75.128441 | Q22: =P22*Q$11 -> 72.874588 | ... Z22: =Y22*Z$11 -> 55.401525
B23: Coh M8 | J23: =J$7 -> 100 | K23: =J23*K$11 -> 95 | L23: =K23*L$11 -> 91.2 | M23: =L23*M$11 -> 87.552 | N23: =M23*N$11 -> 84.04992 | O23: =N23*O$11 -> 81.528422 | P23: =O23*P$11 -> 79.08257 | Q23: =P23*Q$11 -> 76.710093 | R23: =Q23*R$11 -> 74.40879 | ... Z23: =Y23*Z$11 -> 58.317395
B24: Coh M9 | K24: =K$7 -> 100 | L24: =K24*L$11 -> 96 | M24: =L24*M$11 -> 92.16 | N24: =M24*N$11 -> 88.4736 | O24: =N24*O$11 -> 85.819392 | P24: =O24*P$11 -> 83.24481 | Q24: =P24*Q$11 -> 80.747466 | R24: =Q24*R$11 -> 78.325042 | S24: =R24*S$11 -> 75.975291 | ... Z24: =Y24*Z$11 -> 61.386732
B25: Coh M10 | L25: =L$7 -> 150 | M25: =L25*M$11 -> 144 | N25: =M25*N$11 -> 138.24 | O25: =N25*O$11 -> 134.0928 | P25: =O25*P$11 -> 130.07002 | Q25: =P25*Q$11 -> 126.16792 | R25: =Q25*R$11 -> 122.38288 | S25: =R25*S$11 -> 118.71139 | T25: =S25*T$11 -> 115.15005 | ... Z25: =Y25*Z$11 -> 95.916768
B26: Coh M11 | M26: =M$7 -> 150 | N26: =M26*N$11 -> 144 | O26: =N26*O$11 -> 139.68 | P26: =O26*P$11 -> 135.4896 | Q26: =P26*Q$11 -> 131.42491 | R26: =Q26*R$11 -> 127.48216 | S26: =R26*S$11 -> 123.6577 | T26: =S26*T$11 -> 119.94797 | U26: =T26*U$11 -> 116.34953 | ... Z26: =Y26*Z$11 -> 99.9133
B27: Coh M12 | N27: =N$7 -> 150 | O27: =N27*O$11 -> 145.5 | P27: =O27*P$11 -> 141.135 | Q27: =P27*Q$11 -> 136.90095 | R27: =Q27*R$11 -> 132.79392 | S27: =R27*S$11 -> 128.8101 | T27: =S27*T$11 -> 124.9458 | U27: =T27*U$11 -> 121.19743 | V27: =U27*V$11 -> 117.5615 | ... Z27: =Y27*Z$11 -> 104.07635
B28: Coh M13 | O28: =O$7 -> 180 | P28: =O28*P$11 -> 174.6 | Q28: =P28*Q$11 -> 169.362 | R28: =Q28*R$11 -> 164.28114 | S28: =R28*S$11 -> 159.35271 | T28: =S28*T$11 -> 154.57212 | U28: =T28*U$11 -> 149.93496 | V28: =U28*V$11 -> 145.43691 | W28: =V28*W$11 -> 141.0738 | ... Z28: =Y28*Z$11 -> 128.75425
B29: Coh M14 | P29: =P$7 -> 180 | Q29: =P29*Q$11 -> 174.6 | R29: =Q29*R$11 -> 169.362 | S29: =R29*S$11 -> 164.28114 | T29: =S29*T$11 -> 159.35271 | U29: =T29*U$11 -> 154.57212 | V29: =U29*V$11 -> 149.93496 | W29: =V29*W$11 -> 145.43691 | X29: =W29*X$11 -> 141.0738 | ... Z29: =Y29*Z$11 -> 132.73634
B30: Coh M15 | Q30: =Q$7 -> 180 | R30: =Q30*R$11 -> 174.6 | S30: =R30*S$11 -> 169.362 | T30: =S30*T$11 -> 164.28114 | U30: =T30*U$11 -> 159.35271 | V30: =U30*V$11 -> 154.57212 | W30: =V30*W$11 -> 149.93496 | X30: =W30*X$11 -> 145.43691 | Y30: =X30*Y$11 -> 141.0738 | Z30: =Y30*Z$11 -> 136.84159
B31: Coh M16 | R31: =R$7 -> 180 | S31: =R31*S$11 -> 174.6 | T31: =S31*T$11 -> 169.362 | U31: =T31*U$11 -> 164.28114 | V31: =U31*V$11 -> 159.35271 | W31: =V31*W$11 -> 154.57212 | X31: =W31*X$11 -> 149.93496 | Y31: =X31*Y$11 -> 145.43691 | Z31: =Y31*Z$11 -> 141.0738
B32: Coh M17 | S32: =S$7 -> 180 | T32: =S32*T$11 -> 174.6 | U32: =T32*U$11 -> 169.362 | V32: =U32*V$11 -> 164.28114 | W32: =V32*W$11 -> 159.35271 | X32: =W32*X$11 -> 154.57212 | Y32: =X32*Y$11 -> 149.93496 | Z32: =Y32*Z$11 -> 145.43691
B33: Coh M18 | T33: =T$7 -> 180 | U33: =T33*U$11 -> 174.6 | V33: =U33*V$11 -> 169.362 | W33: =V33*W$11 -> 164.28114 | X33: =W33*X$11 -> 159.35271 | Y33: =X33*Y$11 -> 154.57212 | Z33: =Y33*Z$11 -> 149.93496
B34: Coh M19 | U34: =U$7 -> 200 | V34: =U34*V$11 -> 194 | W34: =V34*W$11 -> 188.18 | X34: =W34*X$11 -> 182.5346 | Y34: =X34*Y$11 -> 177.05856 | Z34: =Y34*Z$11 -> 171.74681
B35: Coh M20 | V35: =V$7 -> 200 | W35: =V35*W$11 -> 194 | X35: =W35*X$11 -> 188.18 | Y35: =X35*Y$11 -> 182.5346 | Z35: =Y35*Z$11 -> 177.05856
B36: Coh M21 | W36: =W$7 -> 200 | X36: =W36*X$11 -> 194 | Y36: =X36*Y$11 -> 188.18 | Z36: =Y36*Z$11 -> 182.5346
B37: Coh M22 | X37: =X$7 -> 200 | Y37: =X37*Y$11 -> 194 | Z37: =Y37*Z$11 -> 188.18
B38: Coh M23 | Y38: =Y$7 -> 200 | Z38: =Y38*Z$11 -> 194
B39: Coh M24 | Z39: =Z$7 -> 200
B40: Cuentas activas totales (sum cohortes) | C40: =SUM(C16:C39) -> 5 | D40: =SUM(D16:D39) -> 10 | E40: =SUM(E16:E39) -> 24.2 | F40: =SUM(F16:F39) -> 37.264 | G40: =SUM(G16:G39) -> 85.02816 | H40: =SUM(H16:H39) -> 129.92647 | I40: =SUM(I16:I39) -> 223.43015 | J40: =SUM(J16:J39) -> 312.25864 | ... Z40: =SUM(Z16:Z39) -> 2491.6921
B42: REVENUE Y UNIT ECONOMICS MENSUALES
B43: Revenue mensual (€) | C43: =C40*C10 -> 0 | D43: =D40*D10 -> 0 | E43: =E40*E10 -> 72.6 | F43: =F40*F10 -> 111.792 | G43: =G40*G10 -> 739.74499 | H43: =H40*H10 -> 1130.3603 | I43: =I40*I10 -> 3463.1673 | J43: =J40*J10 -> 4840.0089 | ... Z43: =Z40*Z10 -> 79983.316
B44: GMV mensual (€) | C44: =C40*Phases!C16 -> 0 | D44: =D40*Phases!C16 -> 0 | E44: =E40*Phases!D16 -> 726 | F44: =F40*Phases!D16 -> 1117.92 | G44: =G40*Phases!E16 -> 5101.6896 | H44: =H40*Phases!E16 -> 7795.5882 | I44: =I40*Phases!F16 -> 22343.015 | J44: =J40*Phases!F16 -> 31225.864 | K44: =K40*Phases!F16 -> 39664.571 | L44: =L40*Phases!G16 -> 69001.384 | M44: =M40*Phases!G16 -> 85741.329 | N44: =N40*Phases!G16 -> 101811.68 | O44: =O40*Phases!H16 -> 140950.76 | P44: =P40*Phases!H16 -> 163722.24 | Q44: =Q40*Phases!H16 -> 185810.57 | R44: =R40*Phases!H16 -> 207236.25 | S44: =S40*Phases!H16 -> 228019.17 | T44: =T40*Phases!H16 -> 248178.59 | U44: =U40*Phases!I16 -> 297806.56 | V44: =V40*Phases!I16 -> 321872.36 | W44: =W40*Phases!I16 -> 345216.19 | X44: =X40*Phases!I16 -> 367859.7 | Y44: =Y40*Phases!I16 -> 389823.91 | Z44: =Z40*Phases!I16 -> 411129.19
B45: COGS mensual (€) | C45: =C40*Phases!C31 -> 2.5 | D45: =D40*Phases!C31 -> 5 | E45: =E40*Phases!D31 -> 42.35 | F45: =F40*Phases!D31 -> 65.212 | G45: =G40*Phases!E31 -> 239.77941 | H45: =H40*Phases!E31 -> 366.39265 | I45: =I40*Phases!F31 -> 893.72059 | J45: =J40*Phases!F31 -> 1249.0346 | K45: =K40*Phases!F31 -> 1586.5828 | L45: =L40*Phases!G31 -> 2706.9774 | M45: =M40*Phases!G31 -> 3363.6983 | N45: =N40*Phases!G31 -> 3994.1504 | O45: =O40*Phases!H31 -> 4886.293 | P45: =P40*Phases!H31 -> 5675.7042 | Q45: =Q40*Phases!H31 -> 6441.4331 | R45: =R40*Phases!H31 -> 7184.1901 | S45: =S40*Phases!H31 -> 7904.6644 | T45: =T40*Phases!H31 -> 8603.5245 | U45: =U40*Phases!I31 -> 10414.205 | V45: =V40*Phases!I31 -> 11255.779 | W45: =W40*Phases!I31 -> 12072.106 | X45: =X40*Phases!I31 -> 12863.942 | Y45: =Y40*Phases!I31 -> 13632.024 | Z45: =Z40*Phases!I31 -> 14377.063
B46: Gross profit (€) | C46: =C43-C45 -> -2.5 | D46: =D43-D45 -> -5 | E46: =E43-E45 -> 30.25 | F46: =F43-F45 -> 46.58 | G46: =G43-G45 -> 499.96558 | H46: =H43-H45 -> 763.96765 | I46: =I43-I45 -> 2569.4467 | J46: =J43-J45 -> 3590.9744 | ... Z46: =Z43-Z45 -> 65606.253
...

Sheet Use of Funds
B2: USO DE FONDOS · RONDA PRE-SEED €300K
B3: Asignación por categoría y tramo. Cada tramo está condicionado a hitos verificables (gates).
B5: ASIGNACIÓN POR CATEGORÍA · 24 MESES
B6: Categoría | C6: Tramo 1 M1-M6 | D6: Tramo 2 M7-M12 | E6: Tramo 3 M13-M18 | F6: Tramo 4 M19-M24 | G6: TOTAL
B7: Salarios fully-loaded (founder + freelancers) | C7: 18000 | D7: 33000 | E7: 51000 | F7: 63000 | G7: =SUM(C7:F7) -> 165000
B8: Infraestructura tecnológica (Lovable, Supabase, Stripe) | C8: 1500 | D8: 2400 | E8: 4200 | F8: 6400 | G8: =SUM(C8:F8) -> 14500
B9: Marketing pagado / CAC (Meta, Google, partners) | C9: 6000 | D9: 18000 | E9: 22000 | F9: 24000 | G9: =SUM(C9:F9) -> 70000
B10: Legal, contabilidad, registro marca, asesoría | C10: 1500 | D10: 2100 | E10: 3000 | F10: 3600 | G10: =SUM(C10:F10) -> 10200
B11: Working capital (escrow, garantías, contingencias) | C11: 2500 | D11: 3500 | E11: 5000 | F11: 5000 | G11: =SUM(C11:F11) -> 16000
B12: Reserva estratégica / buffer (15%) | C12: 0 | D12: 0 | E12: 0 | F12: 24300 | G12: =SUM(C12:F12) -> 24300
B13: Subtotal por tramo (€) | C13: =SUM(C7:C12) -> 29500 | D13: =SUM(D7:D12) -> 59000 | E13: =SUM(E7:E12) -> 85200 | F13: =SUM(F7:F12) -> 126300 | G13: =SUM(C13:F13) -> 300000
B14: % del round | C14: =C13/$G$13 -> 0.098333333 | D14: =D13/$G$13 -> 0.19666667 | E14: =E13/$G$13 -> 0.284 | F14: =F13/$G$13 -> 0.421 | G14: =SUM(C14:F14) -> 1
B16: GATES DE LIBERACIÓN POR TRAMO
B17: Tramo | C17: Mes activación | D17: Hito requerido
B18: Tramo 1 | C18: M1 (al cierre de ronda) | D18: Capital cerrado · MVP en Lovable funcional · 20 sellers preonboarded
B19: Tramo 2 | C19: M7 | D19: ≥10 transacciones reales completadas · LTV:CAC ≥ 3× sostenido · Churn anual <50%
B20: Tramo 3 | C20: M13 | D20: ≥200 cuentas activas pagadoras · MRR ≥ €5K · GM real ≥70%
B21: Tramo 4 | C21: M19 | D21: ≥800 cuentas activas pagadoras · MRR ≥ €25K · NRR ≥100% · Plan EU validado
B23: ANÁLISIS DE BURN RATE
B24: Burn rate medio mensual (€/mes) | C24: =C13/6 -> 4916.6667 | D24: =D13/6 -> 9833.3333 | E24: =E13/6 -> 14200 | F24: =F13/6 -> 21050 | G24: =G13/24 -> 12500
B25: Cash al final de tramo (€) | C25: =300000-C13 -> 270500 | D25: =C25-D13 -> 211500 | E25: =D25-E13 -> 126300 | F25: =E25-F13 -> 0
B26: Runway al ritmo de burn de tramo (meses) | C26: =IFERROR(C25/C24,0) -> 55.016949 | D26: =IFERROR(D25/D24,0) -> 21.508475 | E26: =IFERROR(E25/E24,0) -> 8.8943662 | F26: =IFERROR(F25/F24,0) -> 0
B28: VALIDACIÓN
B29: Capital total asignado vs €300K objetivo | C29: =G13 -> 300000 | D29: Diferencia | E29: =300000-G13 -> 0 | F29: OK? | G29: =IF(ABS(300000-G13)<1000,"OK","REVISAR") -> OK

Sheet KPI Goldman
B2: KPIs INSTITUCIONALES · GRADO GOLDMAN/MS
B3: Métricas que un comité de inversión sofisticado va a auditar. Cada una con benchmark y status semaforico.
B5: GROWTH & EFICIENCIA
B6: KPI | C6: Valor M24 | D6: Benchmark institucional | E6: Status
B7: MRR a M24 (€) | C7: ='Monthly 24m'!Z43 -> 79983.316 | D7: Pre-seed: €5-15K · Seed: €25-50K | E7: =IF(C7>=25000,"VERDE",IF(C7>=10000,"AMBAR","ROJO")) -> VERDE
B8: ARR run-rate M24 (€) | C8: ='Monthly 24m'!Z64 -> 959799.79 | D8: Pre-seed graduate: €100-300K · Series A: €1M+ | E8: =IF(C8>=300000,"VERDE",IF(C8>=100000,"AMBAR","ROJO")) -> VERDE
B9: Magic Number (Net new ARR / S&M spend) | C9: =SUM('Monthly 24m'!C65:Z65)/SUM('Monthly 24m'!C51:Z51) -> 2.4422387 | D9: >0.75 = green; >1.0 = excelente growth efficiency | E9: =IF(C9>=0.75,"VERDE",IF(C9>=0.5,"AMBAR","ROJO")) -> VERDE
B10: Burn Multiple (capital quemado / ARR neto) | C10: =IFERROR((300000-MIN('Monthly 24m'!C59:Z59))/('Monthly 24m'!Z64),99) -> 0.1634724 | D10: <1× excelente · 1-2× bueno · >2× problema | E10: =IF(C10<=1,"VERDE",IF(C10<=2,"AMBAR","ROJO")) -> VERDE
B11: Rule of 40 (Growth + EBITDA margin) | C11: =IFERROR('Monthly 24m'!Z64/'Monthly 24m'!N64-1+'Monthly 24m'!Z53*12/'Monthly 24m'!Z64,0) -> 4.2540638 | D11: ≥40% indicates SaaS health | E11: =IF(C11>=0.4,"VERDE",IF(C11>=0,"AMBAR","ROJO")) -> VERDE
B13: RETENTION & EXPANSION
B14: KPI | C14: Valor | D14: Benchmark | E14: Status
B15: NRR (Net Revenue Retention) — base | C15: =Assumptions!D28 -> 1.05 | D15: >100% expansión · >120% world-class | E15: =IF(C15>=1.2,"VERDE",IF(C15>=1,"AMBAR","ROJO")) -> AMBAR
B16: Gross logo retention anual | C16: =1-Assumptions!D27 -> 0.6 | D16: >70% marketplace B2B · >85% SaaS | E16: =IF(C16>=0.7,"VERDE",IF(C16>=0.5,"AMBAR","ROJO")) -> AMBAR
B17: LTV : CAC | C17: =LTV!D16/CAC!D17 -> 5.1378592 | D17: >3× sano · >5× excelente | E17: =IF(C17>=3,"VERDE",IF(C17>=2,"AMBAR","ROJO")) -> VERDE
B18: CAC Payback | C18: =CAC!D17/(LTV!D9/12) -> 6.6731518 | D18: <12 mo sano · <18 mo aceptable | E18: =IF(C18<=12,"VERDE",IF(C18<=18,"AMBAR","ROJO")) -> VERDE
B20: QUALITY OF GROWTH
B21: KPI | C21: Valor | D21: Benchmark | E21: Status
B22: Gross Margin real | C22: ='Gross Margin'!D24 -> 0.78593272 | D22: >70% marketplace · >75% SaaS | E22: =IF(C22>=0.7,"VERDE",IF(C22>=0.6,"AMBAR","ROJO")) -> VERDE
B23: CAC blended | C23: =CAC!D17 -> 85.75 | D23: Pre-seed B2B SMB: €50-150 | E23: =IF(C23<=150,"VERDE",IF(C23<=250,"AMBAR","ROJO")) -> VERDE
B24: Cuentas activas M24 | C24: ='Monthly 24m'!Z40 -> 2491.6921 | D24: Pre-seed exit: 500-2000 cuentas | E24: =IF(C24>=1000,"VERDE",IF(C24>=300,"AMBAR","ROJO")) -> VERDE
B25: GMV mensual M24 run-rate (€) | C25: ='Monthly 24m'!Z44 -> 411129.19 | D25: Pre-seed exit: €30-150K/mes | E25: =IF(C25>=50000,"VERDE",IF(C25>=20000,"AMBAR","ROJO")) -> VERDE
B27: TRIGGERS PARA SERIES A
B28: Trigger | C28: Tu valor M24 | D28: Threshold | E28: Listo?
B29: ARR ≥ €1M | C29: ='Monthly 24m'!Z64 -> 959799.79 | D29: 1000000 | E29: =IF(C29>=D29,"SI","NO") -> NO
B30: LTV:CAC ≥ 3× sostenido | C30: =LTV!D16/CAC!D17 -> 5.1378592 | D30: 3 | E30: =IF(C30>=D30,"SI","NO") -> SI
B31: NRR ≥ 100% | C31: =Assumptions!D28 -> 1.05 | D31: 1 | E31: =IF(C31>=D31,"SI","NO") -> SI
B32: YoY growth ≥ 100% | C32: =IFERROR('Monthly 24m'!Z64/'Monthly 24m'!N64-1,0) -> 3.9576738 | D32: 1 | E32: =IF(C32>=D32,"SI","NO") -> SI
B33: Burn multiple ≤ 2× | C33: =IFERROR((300000-MIN('Monthly 24m'!C59:Z59))/('Monthly 24m'!Z64),99) -> 0.1634724 | D33: 2 | E33: =IF(C33<=D33,"SI","NO") -> SI

Sheet Valuation
B2: VALORACIÓN PRE-SEED · COMPARABLES Y CAP TABLE
B5: ESTRUCTURA DE LA RONDA
B6: Variable | C6: Conservador | D6: Base | E6: Agresivo
B7: Round size (€) | C7: 300000 | D7: 300000 | E7: 300000
B8: Valuación post-money (€) | C8: 1500000 | D8: 2000000 | E8: 2500000
B9: Valuación pre-money (€) | C9: =C8-C7 -> 1200000 | D9: =D8-D7 -> 1700000 | E9: =E8-E7 -> 2200000
B10: Dilución del founder (%) | C10: =C7/C8 -> 0.2 | D10: =D7/D8 -> 0.15 | E10: =E7/E8 -> 0.12
B11: % retenido por founder post-ronda | C11: =1-C10 -> 0.8 | D11: =1-D10 -> 0.85 | E11: =1-E10 -> 0.88
B13: ESOP POOL (PARA HIRES POST-RONDA)
B14: ESOP creado pre-ronda (%) | C14: 0.05 | D14: 0.1 | E14: 0.1 | G14: Standard: 10% pre-money para hires de M3-M18.
B15: Founder real post-ronda (con ESOP) | C15: =C11-C14 -> 0.75 | D15: =D11-D14 -> 0.75 | E15: =E11-E14 -> 0.78
B17: COMPARABLES PRE-SEED · MARKETPLACES B2B EUROPA
B18: Empresa | C18: Año | D18: Round (€) | E18: Post-money (€)
B19: Ankorstore (pre-seed equiv.) | C19: 2019 | D19: 1500000 | E19: 6000000
B20: Faire (US, ref.) | C20: 2017 | D20: 4000000 | E20: 15000000
B21: Stoq (UK B2B) | C21: 2021 | D21: 500000 | E21: 3000000
B22: Spanish pre-seed B2B SaaS típico | C22: 2024-25 | D22: 350000 | E22: 2200000
B23: Lanzadera (referencia) | C23: Std | D23: 40000 | E23: 600000
B25: Mediana comparables (referencial) | C25: =MEDIAN(D19:D23)/MEDIAN(E19:E23) -> 0.16666667 | G25: % mediana de dilución en pre-seed comparables.
B27: JUSTIFICACIÓN DE LA VALORACIÓN BASE (€2M post-money)
B28: Argumento | C28: Magnitud
B29: TAM Europa (stock sobrante anual) | C29: €10.000M (Documento Maestro)
B30: SOM realista España + Portugal a 5 años | C30: €60-100M GMV anual
B31: Take rate efectivo objetivo año 5 | C31: 12-15%
B32: ARR objetivo año 5 | C32: €7-12M (rango Series A → Series B)
B33: Múltiplo SaaS B2B Europa (revenue x5-8) | C33: Exit value €40-100M en año 5-7
B34: ROI sobre €300K @ 1% retenido al exit | C34: €100-250K (33-83x)
B35: Validación Goldman/MS: pre-seed razonable 10-20% dilution | C35: €2M post coloca en 15% (centro del rango)
B37: PATH A LA SIGUIENTE RONDA
B38: Siguiente milestone | C38: Cuándo | D38: Tipo de ronda | E38: Round size esperado
B39: MRR €25K + €1M ARR | C39: M18-24 | D39: Seed | E39: €800K-1.5M
B40: MRR €80K + €3M ARR + EU pilot | C40: M30-36 | D40: Series A | E40: €3-5M
B41: MRR €300K + €10M ARR + EU multi-country | C41: M48-60 | D41: Series B | E41: €8-15M

Sheet Assumptions
B2: ASSUMPTIONS · INPUTS DEL MODELO
B3: Celdas en azul sobre fondo amarillo = inputs editables. Celdas en negro = fórmulas. Verdes = referencias cross-sheet.
B5: GMV, AOV Y TAKE RATE
B6: Variable | C6: Pesimista | D6: Base | E6: Optimista
B7: AOV — valor medio por lote (€) | C7: 120 | D7: 200 | E7: 350 | G7: Lote típico de stock sobrante; texto del Documento Maestro: 50–500€.
B8: Transacciones / cliente activo / año | C8: 3 | D8: 6 | E8: 12 | G8: Comerciantes con stock estacional → 2-4 ciclos/año. Power sellers → 12+.
B9: GMV / cliente / año (€) | C9: =C7*C8 -> 360 | D9: =D7*D8 -> 1200 | E9: =E7*E8 -> 4200 | G9: Fórmula: AOV × Frecuencia anual.
B10: Take rate vendedor | C10: 0.06 | D10: 0.08 | E10: 0.1 | G10: Decisión fijada: 8%. Pesimista = pricing erosion. Optimista = premium tier.
B11: Take rate comprador | C11: 0.03 | D11: 0.04 | E11: 0.05 | G11: Cobrado al comprador sobre el valor del lote.
B12: Take rate efectivo blended (sobre GMV) | C12: =C10+C11 -> 0.09 | D12: =D10+D11 -> 0.12 | E12: =E10+E11 -> 0.15 | G12: Suma de comisión vendedor + comprador.
B14: INGRESOS POR SUSCRIPCIÓN PREMIUM (FUTURO)
B15: Variable | C15: Pesimista | D15: Base | E15: Optimista
B16: Precio Premium / mes (€) | C16: 19 | D16: 29 | E16: 49 | G16: Pricing comparable a Faire / Ankorstore Pro tiers.
B17: % adopción Premium (sobre activos) | C17: 0.05 | D17: 0.15 | E17: 0.3 | G17: % de cuentas activas que pagan suscripción.
B18: ARR Premium / cuenta activa | C18: =C16*12*C17 -> 11.4 | D18: =D16*12*D17 -> 52.2 | E18: =E16*12*E17 -> 176.4
B20: MEZCLA DE CUENTAS
B21: Variable | C21: Pesimista | D21: Base | E21: Optimista
B22: % sellers (vs buyers) en base activa | C22: 0.5 | D22: 0.55 | E22: 0.6 | G22: Marketplace simétrico, pero los sellers pagan más → quieres más sellers.
B23: % buyers | C23: =1-C22 -> 0.5 | D23: =1-D22 -> 0.45 | E23: =1-E22 -> 0.4
B25: CHURN & EXPANSIÓN
B26: Variable | C26: Pesimista | D26: Base | E26: Optimista
B27: Gross logo churn anual | C27: 0.6 | D27: 0.4 | E27: 0.25 | G27: Marketplace B2B típicamente 30-50%. Sellers churnan tras liquidar stock.
B28: Net Revenue Retention (expansión) | C28: 0.85 | D28: 1.05 | E28: 1.2 | G28: NRR > 100% = clientes existentes crecen. Esencial para escalar.
B30: COSTOS DIRECTOS (COGS)
B31: Variable | C31: Pesimista | D31: Base | E31: Optimista
B32: Comisión Stripe Connect (% sobre GMV) | C32: 0.025 | D32: 0.02 | E32: 0.015 | G32: Stripe Connect estándar: 1.4% + 0.25€ EU + ~0.5% platform fee.
B33: Hosting + infra / cuenta / año (€) | C33: 8 | D33: 5 | E33: 3 | G33: Supabase + Lovable allocados. Coste fijo se vuelve marginal con escala.
B34: APIs terceros / cuenta / año (€) | C34: 4 | D34: 2 | E34: 1 | G34: Email (Brevo), KYC, antifraude, S3 imágenes.
B35: Soporte tier-1 / cuenta / año (€) | C35: 18 | D35: 10 | E35: 5 | G35: Disputas de marketplace son intensivas. Subestimado en planes founder-led.
B36: Verificación KYC vendedor / cuenta / año (€) | C36: 2 | D36: 1 | E36: 0.5 | G36: Onfido / Veriff. Amortizado por años de vida del cliente.
B38: CAC POR CANAL Y MIX
B39: Canal | C39: CAC (€) | D39: % del mix | E39: Notas
B40: Comunidades Telegram / Discord (orgánico) | C40: 15 | D40: 0.2 | E40: Tiempo del founder valorado
B41: Outreach directo founder-led | C41: 80 | D41: 0.25 | E41: 1h calificar + 2h cierre × 30€/h
B42: SEO + Contenido | C42: 45 | D42: 0.15 | E42: Escala bien; lag 6-12 meses
B43: Partnerships academias dropshipping | C43: 60 | D43: 0.2 | E43: % revenue share + bonus
B44: Paid ads (Meta / Google) | C44: 220 | D44: 0.2 | E44: B2B SMB cuesta caro; CTR bajo
B45: Total mix | D45: =SUM(D40:D44) -> 1 | F45: Debe sumar 100%.
B46: CAC blended (base) | C46: =SUMPRODUCT(C40:C44,D40:D44) -> 85.75
B48: OPEX FIJO (PARA BREAK-EVEN)
...

Sheet Gross Margin
B2: GROSS MARGIN · MARGEN BRUTO REAL
B3: Costos directos por cuenta activa/año. Compara margen bruto 'de fantasía' vs. ajustado.
B5: REVENUE POR CUENTA
B6: Variable | C6: Pesimista | D6: Base | E6: Optimista
B7: GMV / cuenta activa / año (€) | C7: =Assumptions!C9 -> 360 | D7: =Assumptions!D9 -> 1200 | E7: =Assumptions!E9 -> 4200
B8: Take rate efectivo | C8: =Assumptions!C12 -> 0.09 | D8: =Assumptions!D12 -> 0.12 | E8: =Assumptions!E12 -> 0.15
B9: Revenue comisión / año (€) | C9: =C7*C8 -> 32.4 | D9: =D7*D8 -> 144 | E9: =E7*E8 -> 630
B10: Revenue Premium / año (€) | C10: =Assumptions!C18 -> 11.4 | D10: =Assumptions!D18 -> 52.2 | E10: =Assumptions!E18 -> 176.4
B11: ARPA total / año (€) | C11: =C9+C10 -> 43.8 | D11: =D9+D10 -> 196.2 | E11: =E9+E10 -> 806.4 | G11: Fórmula: (GMV × take rate) + (Premium × % adopción × 12).
B13: COGS DETALLADO POR CUENTA / AÑO
B14: Concepto | C14: Pesimista | D14: Base | E14: Optimista
B15: Procesamiento de pagos (Stripe Connect) | C15: =C7*Assumptions!C32 -> 9 | D15: =D7*Assumptions!D32 -> 24 | E15: =E7*Assumptions!E32 -> 63 | G15: Fórmula: GMV × % Stripe. ESTE es el COGS más grande.
B16: Hosting + servidores (Supabase + Lovable) | C16: =Assumptions!C33 -> 8 | D16: =Assumptions!D33 -> 5 | E16: =Assumptions!E33 -> 3
B17: APIs terceros (email, S3, antifraude) | C17: =Assumptions!C34 -> 4 | D17: =Assumptions!D34 -> 2 | E17: =Assumptions!E34 -> 1
B18: Soporte tier-1 (disputas, onboarding) | C18: =Assumptions!C35 -> 18 | D18: =Assumptions!D35 -> 10 | E18: =Assumptions!E35 -> 5
B19: Verificación KYC vendedor | C19: =Assumptions!C36 -> 2 | D19: =Assumptions!D36 -> 1 | E19: =Assumptions!E36 -> 0.5
B20: TOTAL COGS / cuenta / año | C20: =SUM(C15:C19) -> 41 | D20: =SUM(D15:D19) -> 42 | E20: =SUM(E15:E19) -> 72.5
B22: GROSS PROFIT & GROSS MARGIN
B23: Gross Profit / cuenta / año (€) | C23: =C11-C20 -> 2.8 | D23: =D11-D20 -> 154.2 | E23: =E11-E20 -> 733.9 | G23: Fórmula: ARPA − COGS.
B24: Gross Margin (real) | C24: =IFERROR(C23/C11,0) -> 0.063926941 | D24: =IFERROR(D23/D11,0) -> 0.78593272 | E24: =IFERROR(E23/E11,0) -> 0.91009425
B26: MARGEN 'DE FANTASÍA' vs. AJUSTADO
B27: Margen 'de fantasía' (solo ignorando Stripe y soporte) | C27: =IFERROR((C11-C16-C17-C19)/C11,0) -> 0.6803653 | D27: =IFERROR((D11-D16-D17-D19)/D11,0) -> 0.95922528 | E27: =IFERROR((E11-E16-E17-E19)/E11,0) -> 0.99441964 | G27: Trampa común en pitch decks: ignorar el coste real de payment processing y soporte.
B28: Diferencia (puntos porcentuales) | C28: =C27-C24 -> 0.61643836 | D28: =D27-D24 -> 0.17329256 | E28: =E27-E24 -> 0.084325397
B30: GROSS MARGIN BASE (referencia Dashboard) | C30: =D24 -> 0.78593272

Sheet LTV
B2: LTV · LIFETIME VALUE
B3: LTV = (ARPA × Gross Margin) / Churn. Modelo de cohorte simple, sin discount rate (conservador).
B5: INPUTS LTV
B6: Variable | C6: Pesimista | D6: Base | E6: Optimista
B7: ARPA / año (€) | C7: ='Gross Margin'!C11 -> 43.8 | D7: ='Gross Margin'!D11 -> 196.2 | E7: ='Gross Margin'!E11 -> 806.4
B8: Gross Margin | C8: ='Gross Margin'!C24 -> 0.063926941 | D8: ='Gross Margin'!D24 -> 0.78593272 | E8: ='Gross Margin'!E24 -> 0.91009425
B9: Gross Profit / cuenta / año (€) | C9: =C7*C8 -> 2.8 | D9: =D7*D8 -> 154.2 | E9: =E7*E8 -> 733.9
B10: Gross logo churn anual | C10: =Assumptions!C27 -> 0.6 | D10: =Assumptions!D27 -> 0.4 | E10: =Assumptions!E27 -> 0.25
B11: Net Revenue Retention (NRR) | C11: =Assumptions!C28 -> 0.85 | D11: =Assumptions!D28 -> 1.05 | E11: =Assumptions!E28 -> 1.2
B12: Churn neto efectivo (revenue churn − expansión) | C12: =MAX(C10-(C11-1),0.05) -> 0.75 | D12: =MAX(D10-(D11-1),0.05) -> 0.35 | E12: =MAX(E10-(E11-1),0.05) -> 0.05 | G12: Fórmula: Churn − (NRR − 1). Floor 5% para evitar LTV infinito.
B14: CÁLCULO LTV
B15: LTV simple (sin Gross Margin) | C15: =C7/C12 -> 58.4 | D15: =D7/D12 -> 560.57143 | E15: =E7/E12 -> 16128 | G15: Fórmula: ARPA / Churn neto. SIN considerar margen → métrica vanidosa.
B16: LTV ajustado por Gross Margin | C16: =C9/C12 -> 3.7333333 | D16: =D9/D12 -> 440.57143 | E16: =E9/E12 -> 14678 | G16: Fórmula: (ARPA × GM) / Churn neto. ESTE es el LTV real.
B17: Vida media del cliente (años) | C17: =1/C12 -> 1.3333333 | D17: =1/D12 -> 2.8571429 | E17: =1/E12 -> 20
B19: SENSIBILIDAD LTV — CHURN × NRR (BASE)
B20: Churn / NRR | C20: 0.85 | D20: 1 | E20: 1.1 | F20: 1.2
B21: 0.2 | C21: =$D$7*$D$8/MAX($B21-(C$20-1),0.05) -> 440.57143 | D21: =$D$7*$D$8/MAX($B21-(D$20-1),0.05) -> 771 | E21: =$D$7*$D$8/MAX($B21-(E$20-1),0.05) -> 1542 | F21: =$D$7*$D$8/MAX($B21-(F$20-1),0.05) -> 3084
B22: 0.4 | C22: =$D$7*$D$8/MAX($B22-(C$20-1),0.05) -> 280.36364 | D22: =$D$7*$D$8/MAX($B22-(D$20-1),0.05) -> 385.5 | E22: =$D$7*$D$8/MAX($B22-(E$20-1),0.05) -> 514 | F22: =$D$7*$D$8/MAX($B22-(F$20-1),0.05) -> 771
B23: 0.6 | C23: =$D$7*$D$8/MAX($B23-(C$20-1),0.05) -> 205.6 | D23: =$D$7*$D$8/MAX($B23-(D$20-1),0.05) -> 257 | E23: =$D$7*$D$8/MAX($B23-(E$20-1),0.05) -> 308.4 | F23: =$D$7*$D$8/MAX($B23-(F$20-1),0.05) -> 385.5
B24: Churn base (publicado) | C24: =D10 -> 0.4
B26: ANCHORS PARA DASHBOARD
B27: ARPA base | C27: =D7 -> 196.2
B28: ARPA base (publicado) | C28: =D7 -> 196.2
B30: Contribution Margin / cliente / año (€) | C30: =D9 -> 154.2
B32: LTV BASE (publicado) | C32: =D16 -> 440.57143

Sheet CAC
B2: CAC · CUSTOMER ACQUISITION COST
B3: CAC blended por canal y CAC payback period. Benchmark SaaS sano: payback < 12-18 meses.
B5: DESGLOSE POR CANAL
B6: Canal | C6: CAC (€) | D6: % mix | E6: CAC × mix | F6: Payback (meses)
B7: Comunidades Telegram / Discord (orgánico) | C7: =Assumptions!C40 -> 15 | D7: =Assumptions!D40 -> 0.2 | E7: =C7*D7 -> 3 | F7: =C7/(LTV!$D$9/12) -> 1.1673152
B8: Outreach directo founder-led | C8: =Assumptions!C41 -> 80 | D8: =Assumptions!D41 -> 0.25 | E8: =C8*D8 -> 20 | F8: =C8/(LTV!$D$9/12) -> 6.2256809
B9: SEO + Contenido (orgánico) | C9: =Assumptions!C42 -> 45 | D9: =Assumptions!D42 -> 0.15 | E9: =C9*D9 -> 6.75 | F9: =C9/(LTV!$D$9/12) -> 3.5019455
B10: Partnerships academias dropshipping | C10: =Assumptions!C43 -> 60 | D10: =Assumptions!D43 -> 0.2 | E10: =C10*D10 -> 12 | F10: =C10/(LTV!$D$9/12) -> 4.6692607
B11: Paid ads (Meta / Google) | C11: =Assumptions!C44 -> 220 | D11: =Assumptions!D44 -> 0.2 | E11: =C11*D11 -> 44 | F11: =C11/(LTV!$D$9/12) -> 17.120623
B12: Total mix | D12: =SUM(D7:D11) -> 1
B13: CAC blended (base) | C13: =SUM(E7:E11) -> 85.75
B15: ESCENARIOS CAC
B16: Variable | C16: Pesimista (+30%) | D16: Base | E16: Optimista (-30%)
B17: CAC blended (€) | C17: =C13*1.3 -> 111.475 | D17: =C13 -> 85.75 | E17: =C13*0.7 -> 60.025
B18: Payback period | C18: =C17/(LTV!$C$9/12) -> 477.75 | D18: =D17/(LTV!$D$9/12) -> 6.6731518 | E18: =E17/(LTV!$E$9/12) -> 0.98146886
B19: CAC BASE (publicado) | C19: =D17 -> 85.75
B21: RATIO LTV : CAC
B22: Pesimista | C22: =LTV!C16/C17 -> 0.033490319 | F22: Si <1: cada cliente quema dinero. ROJO.
B23: Base | C23: =LTV!D16/D17 -> 5.1378592 | F23: Benchmark sano: > 3x.
B24: Optimista | C24: =LTV!E16/E17 -> 244.53145 | F24: > 5x es excelente; >7x sugiere underspend en CAC.
B26: DIAGNÓSTICO POR ESCENARIO
B27: Escenario | C27: LTV:CAC | D27: Payback | E27: Veredicto
B28: Pesimista | C28: =C22 -> 0.033490319 | D28: =C18 -> 477.75 | E28: =IF(C28>=3,"OK",IF(C28>=2,"VENTANA AJUSTADA","ROTO — pivota o baja CAC")) -> ROTO — pivota o baja CAC
B29: Base | C29: =C23 -> 5.1378592 | D29: =D18 -> 6.6731518 | E29: =IF(C29>=3,"OK",IF(C29>=2,"VENTANA AJUSTADA","ROTO — pivota o baja CAC")) -> OK
B30: Optimista | C30: =C24 -> 244.53145 | D30: =E18 -> 0.98146886 | E30: =IF(C30>=3,"OK",IF(C30>=2,"VENTANA AJUSTADA","ROTO — pivota o baja CAC")) -> OK

Sheet Cohort Cash Flow
B2: CASH FLOW POR COHORTE · BREAK-EVEN POR CLIENTE
B3: Fila por mes desde adquisición. Negativo = aún no ha pagado el CAC. Mes que cruza positivo = payback.
B5: Concepto / mes | C5: M0 | D5: M1 | E5: M2 | F5: M3 | G5: M4 | H5: M5 | I5: M6 | J5: M7 | K5: M8 | L5: M9 | M5: M10 | N5: M11 | O5: M12 | P5: M13 | Q5: M14 | R5: M15 | S5: M16 | T5: M17 | U5: M18 | V5: M19 | W5: M20 | X5: M21 | Y5: M22 | Z5: M23 | AA5: M24
B6: Revenue mensual / cliente (€) | C6: =-CAC!$D$17 -> -85.75 | D6: =LTV!$D$7/12 -> 16.35 | E6: =LTV!$D$7/12 -> 16.35 | F6: =LTV!$D$7/12 -> 16.35 | G6: =LTV!$D$7/12 -> 16.35 | H6: =LTV!$D$7/12 -> 16.35 | I6: =LTV!$D$7/12 -> 16.35 | J6: =LTV!$D$7/12 -> 16.35 | K6: =LTV!$D$7/12 -> 16.35 | ... AA6: =LTV!$D$7/12 -> 16.35
B7: COGS mensual / cliente (€) | C7: =0 -> 0 | D7: =-'Gross Margin'!$D$20/12 -> -3.5 | E7: =-'Gross Margin'!$D$20/12 -> -3.5 | F7: =-'Gross Margin'!$D$20/12 -> -3.5 | G7: =-'Gross Margin'!$D$20/12 -> -3.5 | H7: =-'Gross Margin'!$D$20/12 -> -3.5 | I7: =-'Gross Margin'!$D$20/12 -> -3.5 | J7: =-'Gross Margin'!$D$20/12 -> -3.5 | K7: =-'Gross Margin'!$D$20/12 -> -3.5 | ... AA7: =-'Gross Margin'!$D$20/12 -> -3.5
B8: Contribución mensual neta (€) | C8: =C6+C7 -> -85.75 | D8: =D6+D7 -> 12.85 | E8: =E6+E7 -> 12.85 | F8: =F6+F7 -> 12.85 | G8: =G6+G7 -> 12.85 | H8: =H6+H7 -> 12.85 | I8: =I6+I7 -> 12.85 | J8: =J6+J7 -> 12.85 | ... AA8: =AA6+AA7 -> 12.85
B9: Cash flow acumulado (€) | C9: =C8 -> -85.75 | D9: =C9+D8 -> -72.9 | E9: =D9+E8 -> -60.05 | F9: =E9+F8 -> -47.2 | G9: =F9+G8 -> -34.35 | H9: =G9+H8 -> -21.5 | I9: =H9+I8 -> -8.65 | J9: =I9+J8 -> 4.2 | K9: =J9+K8 -> 17.05 | ... AA9: =Z9+AA8 -> 222.65
B10: Payback alcanzado? | C10: =IF(C9>=0,"SI","NO") -> NO | D10: =IF(AND(C9<0,D9>=0),"PAYBACK",IF(D9>=0,"+","")) | E10: =IF(AND(D9<0,E9>=0),"PAYBACK",IF(E9>=0,"+","")) | F10: =IF(AND(E9<0,F9>=0),"PAYBACK",IF(F9>=0,"+","")) | G10: =IF(AND(F9<0,G9>=0),"PAYBACK",IF(G9>=0,"+","")) | H10: =IF(AND(G9<0,H9>=0),"PAYBACK",IF(H9>=0,"+","")) | I10: =IF(AND(H9<0,I9>=0),"PAYBACK",IF(I9>=0,"+","")) | J10: =IF(AND(I9<0,J9>=0),"PAYBACK",IF(J9>=0,"+","")) -> PAYBACK | K10: =IF(AND(J9<0,K9>=0),"PAYBACK",IF(K9>=0,"+","")) -> + | ... AA10: =IF(AND(Z9<0,AA9>=0),"PAYBACK",IF(AA9>=0,"+","")) -> +
B12: RESUMEN COHORTE
B13: CAC pagado en M0 | C13: =CAC!$D$17 -> 85.75
B14: Contribución mensual recurrente | C14: =LTV!$D$7/12-'Gross Margin'!$D$20/12 -> 12.85
B15: Mes de payback (cruce a positivo) | C15: =IFERROR(MATCH(TRUE(),INDEX(C9:Z9>=0,0),0)-1,"No alcanza") -> 7 | G15: Cuenta la primera columna donde el acumulado es ≥ 0.
B16: Vida media (años) | C16: =LTV!$D$17 -> 2.8571429
B17: LTV total (€) | C17: =LTV!$D$16 -> 440.57143
B18: ROI sobre CAC (LTV/CAC) | C18: =C17/C13 -> 5.1378592
B20: IMPACTO DE WORKING CAPITAL · MENSUAL vs ANUAL
B21: Plan | C21: Pago | D21: Cash en M0 | E21: Working capital | F21: Comentario
B22: Premium mensual | C22: 29€ / mes | D22: =Assumptions!D16 -> 29 | E22: =0 -> 0 | F22: Cash flow gradual; menor compromiso → más churn voluntario.
B23: Premium anual (-15% descuento) | C23: 295€ / año | D23: =Assumptions!D16*12*0.85 -> 295.8 | E23: =D23-Assumptions!D16 -> 266.8 | F23: Working capital adelantado: 296€ frente a 29€. 10x más cash en M0.
B24: Cash adicional / cliente anual vs mensual | D24: =D23-D22 -> 266.8 | F24: Cada 100 clientes anuales = ~26K€ de cash adelantado vs mensual.

Sheet Break-even
B2: BREAK-EVEN OPERATIVO Y BURN
B3: Cuántos clientes activos pagadores se necesitan para cubrir OPEX fijo. Cuánto capital se quema antes.
B5: INPUTS BREAK-EVEN
B6: Variable | C6: Pesimista | D6: Base | E6: Optimista
